<?xml version="1.0"?>
<robot xmlns:xacro="http://www.ros.org/wiki/xacro" name="traction_robot">




  <!-- ===================== -->
  <!-- Links (châssis + roues) -->
  <!-- ===================== -->
  <link name="base_link">
    <visual>
      <geometry>
        <box size="0.5 0.3 0.1"/>
      </geometry>
    </visual>
    <collision>
      <geometry>
        <box size="0.5 0.3 0.1"/>
      </geometry>
    </collision>
    <inertial>
      <mass value="1.0"/>
      <inertia ixx="0.1" iyy="0.1" izz="0.1"
               ixy="0.0" ixz="0.0" iyz="0.0"/>
    </inertial>
  </link>

  <link name="wheel_frontleft">
    <visual>
    <origin xyz="0 0 0" rpy="0 0 0"/>
      <geometry>
        <cylinder radius="0.05" length="0.02"/>
      </geometry>
    </visual>
    <collision>
      <origin xyz="0 0 0" rpy="0 0 0"/>
      <geometry>
        <cylinder radius="0.05" length="0.02"/>
      </geometry>
    </collision>  
      <inertial>
      <mass value="0.1"/>
      <inertia ixx="1e-3" iyy="1e-3" izz="1e-3"
               ixy="0.0" ixz="0.0" iyz="0.0"/>
    </inertial>
  </link>

    <link name="wheel_rearleft">
    <visual>
    <origin xyz="0 0 0" rpy="0 0 0"/>
      <geometry>
        <cylinder radius="0.05" length="0.02"/>
      </geometry>
    </visual>
    <collision>
      <origin xyz="0 0 0" rpy="0 0 0"/>
      <geometry>
        <cylinder radius="0.05" length="0.02"/>
      </geometry>
    </collision>  
      <inertial>
      <mass value="0.1"/>
      <inertia ixx="1e-3" iyy="1e-3" izz="1e-3"
               ixy="0.0" ixz="0.0" iyz="0.0"/>
    </inertial>
  </link>

  <link name="wheel_frontright">
    <visual>
        <origin xyz="0 0 0" rpy="0 0 0"/>
      <geometry>
        <cylinder radius="0.05" length="0.02"/>

      </geometry>
    </visual>
    <collision>
      <origin xyz="0 0 0" rpy="0 0 0"/>
      <geometry>
        <cylinder radius="0.05" length="0.02"/>
      </geometry>
    </collision>
      <inertial>
      <mass value="0.1"/>
      <inertia ixx="1e-3" iyy="1e-3" izz="1e-3"
               ixy="0.0" ixz="0.0" iyz="0.0"/>
    </inertial>
  </link>

    <link name="wheel_rearright">
    <visual>
        <origin xyz="0 0 0" rpy="0 0 0"/>
      <geometry>
        <cylinder radius="0.05" length="0.02"/>

      </geometry>
    </visual>
    <collision>
      <origin xyz="0 0 0" rpy="0 0 0"/>
      <geometry>
        <cylinder radius="0.05" length="0.02"/>
      </geometry>
    </collision>
      <inertial>
      <mass value="0.1"/>
      <inertia ixx="1e-3" iyy="1e-3" izz="1e-3"
               ixy="0.0" ixz="0.0" iyz="0.0"/>
    </inertial>
  </link>

  <!-- ===================== -->
  <!-- Joints -->
  <!-- ===================== -->
  <joint name="joint_wheel_frontleft" type="continuous">
    <parent link="base_link"/>
    <child link="wheel_frontleft"/>
    <origin xyz="0.1 0.16 0" rpy="1.5708 0 0"/>
    <axis xyz="0 1 0"/>
  </joint>

  <joint name="joint_wheel_rearleft" type="continuous">
    <parent link="base_link"/>
    <child link="wheel_rearleft"/>
    <origin xyz="-0.1 0.16 0" rpy="1.5708 0 0"/>
    <axis xyz="0 1 0"/>
  </joint>

  <joint name="joint_wheel_frontright" type="continuous">
    <parent link="base_link"/>
    <child link="wheel_frontright"/>
    <origin xyz="0.1 -0.16 0" rpy="1.5708 0 0"/>
    <axis xyz="0 1 0"/>
  </joint>

    <joint name="joint_wheel_rearright" type="continuous">
    <parent link="base_link"/>
    <child link="wheel_rearright"/>
    <origin xyz="-0.1 -0.16 0" rpy="1.5708 0 0"/>
    <axis xyz="0 1 0"/>
  </joint>

  <!-- ===================== -->
  <!-- ROS2 Control -->
  <!-- ===================== -->
  <ros2_control name="traction_system_interface/TractionSystem" type="system">
    <hardware>
      <plugin>traction_system_interface/TractionSystemInterface</plugin>
    </hardware>

    <joint name="joint_wheel_frontleft">
      <command_interface name="velocity"/>
      <state_interface name="position"/>
      <state_interface name="velocity"/>
    </joint>

    <joint name="joint_wheel_frontright">
      <command_interface name="velocity"/>
      <state_interface name="position"/>
      <state_interface name="velocity"/>
    </joint>
  </ros2_control>

  <!-- ===================== -->
  <!-- Gazebo Plugin -->
  <!-- ===================== -->
  <!-- <gazebo>
    <plugin name="ros2_control" filename="libgazebo_ros2_control.so"/>
  </gazebo> -->

</robot>
